Workbook
Name ALICORPC1: cartera!$B$3:$B$1935
Name BAP: cartera!$C$3:$C$1935
Name BBVAC1: cartera!$D$3:$D$1935
Name BVN: cartera!$E$3:$E$1935
Name Columna1: cartera!$A$3:$A$1882
Name COV: cartera!$S$12:$AG$26
Name CPACASC1: cartera!$F$3:$F$1935
Name FECHAS: cartera!$A$3:$A$1935
Name FERREYC1: cartera!$G$3:$G$1935
Name GRAMONC1: cartera!$H$3:$H$1935
Name IFS: cartera!$I$3:$I$1935
Name INRETC1: cartera!$J$3:$J$1935
Name LUSURC1: cartera!$K$3:$K$1935
Name MINSURI1: cartera!$L$3:$L$1935
Name NEXAPEC1: cartera!$M$3:$M$1935
Name RELAPAC1: cartera!$N$3:$N$1935
Name UNACEMC1: cartera!$O$3:$O$1935
Name VOLCABC1: cartera!$P$3:$P$1935

Sheet cartera
B1: RETORNO EN PRIMERAS DIFERENCIAS | S1: RETORNOS PROMEDIOS
A2: FECHAS | B2: ALICORPC1 | C2: BAP | D2: BBVAC1 | E2: BVN | F2: CPACASC1 | G2: FERREYC1 | H2: GRAMONC1 | I2: IFS | J2: INRETC1 | K2: LUSURC1 | L2: MINSURI1 | M2: NEXAPEC1 | N2: RELAPAC1 | O2: UNACEMC1 | P2: VOLCABC1 | S2: ALICORPC1 | T2: BAP | U2: BBVAC1 | V2: BVN | W2: CPACASC1 | X2: FERREYC1 | Y2: GRAMONC1 | Z2: IFS | AA2: INRETC1 | AB2: LUSURC1 | AC2: MINSURI1 | AD2: NEXAPEC1 | AE2: RELAPAC1 | AF2: UNACEMC1 | AG2: VOLCABC1 | AJ2: PORTAFOLIO | BH2: FECHA 10 JUNIO - 11 JUNIO
S3: =AVERAGE(INDIRECT(S2)) -> 0.0036221129 | T3: =AVERAGE(INDIRECT(T2)) -> 0.006696237 | U3: =AVERAGE(INDIRECT(U2)) -> 0.0017842922 | V3: =AVERAGE(INDIRECT(V2)) -> 0.0034742506 | W3: =AVERAGE(INDIRECT(W2)) -> 0.0027539905 | X3: =AVERAGE(INDIRECT(X2)) -> 0.0018866385 | Y3: =AVERAGE(INDIRECT(Y2)) -> 0.0061991071 | Z3: =AVERAGE(INDIRECT(Z2)) -> 0.011442783 | ... AG3: =AVERAGE(INDIRECT(AG2)) -> 0.0015256598 | AJ3: ALICORPC1 | AK3: BAP | AL3: BBVAC1 | AM3: BVN | AN3: CPACASC1 | AO3: FERREYC1 | AP3: GRAMONC1 | AQ3: IFS | AR3: INRETC1 | AS3: LUSURC1 | AT3: MINSURI1 | AU3: NEXAPEC1 | AV3: RELAPAC1 | AW3: UNACEMC1 | AX3: VOLCABC1 | BB3: RIESGO | BC3: RETORNO | BH3: PORTAFOLIO ÓPTIMO <-> RATIO SHARP | BL3: PESOS
A4: 41192 | AI4: PORT 1 | AJ4: 0 | AK4: 0 | AL4: 0 | AM4: 0.1355774 | AN4: 0 | AO4: 0 | AP4: 0.22578415 | AQ4: 0 | AR4: 0.47565157 | AS4: 0 | AT4: 0.16298689 | AU4: 0 | AV4: 0 | AW4: 0 | AX4: 0 | AZ4: =SUM(AJ4:AX4) -> 1 | BB4: {=SQRT(MMULT(MMULT(AJ4:AX4,COV),TRANSPOSE(AJ4:AX4)))} -> 0.015904009 | BC4: {=MMULT($S$3:$AG$3,TRANSPOSE(AJ4:AX4))} -> 0.0053052011 | BD4: Punto portafolio tangente | BH4: Retorno/riesgos | BI4: 0.053516165 | BL4: ALICORPC1 | BM4: BAP | BN4: BBVAC1 | BO4: BVN | BP4: CPACASC1 | BQ4: FERREYC1 | BR4: GRAMONC1 | BS4: IFS | BT4: INRETC1 | BU4: LUSURC1 | BV4: MINSURI1 | BW4: NEXAPEC1 | BX4: RELAPAC1 | BY4: UNACEMC1 | BZ4: VOLCABC1
A5: 41193 | S5: RIESGO (DESVIACIÓN ESTÁNDAR) | AI5: PORT 2 | AJ5: 0 | AK5: 0 | AL5: 0 | AM5: 0.1355774 | AN5: 0 | AO5: 0 | AP5: 0.38877165 | AQ5: 0 | AR5: 0.47565157 | AS5: 0 | AT5: 0 | AU5: 0 | AV5: 0 | AW5: 0 | AX5: 0 | AZ5: =SUM(AJ5:AX5) -> 1.0000006 | BB5: {=SQRT(MMULT(MMULT(AJ5:AX5,COV),TRANSPOSE(AJ5:AX5)))} -> 0.018019442 | BC5: {=MMULT($S$3:$AG$3,TRANSPOSE(AJ5:AX5))} -> 0.0055590384 | BD5: Punto portafolio máx retorno | BH5: RETORNO | BI5: 0.00060527758 | BL5: 0.0051909994 | BM5: 0.087253329 | BN5: 0 | BO5: 0 | BP5: 0 | BQ5: 0 | BR5: 0 | BS5: 0 | BT5: 0.37270664 | BU5: 0.53484904 | BV5: 0 | BW5: 0 | BX5: 0 | BY5: 0 | BZ5: 0
A6: 41194 | S6: ALICORPC1 | T6: BAP | U6: BBVAC1 | V6: BVN | W6: CPACASC1 | X6: FERREYC1 | Y6: GRAMONC1 | Z6: IFS | AA6: INRETC1 | AB6: LUSURC1 | AC6: MINSURI1 | AD6: NEXAPEC1 | AE6: RELAPAC1 | AF6: UNACEMC1 | AG6: VOLCABC1 | AI6: PORT 3 | AJ6: 0 | AK6: 0 | AL6: 0 | AM6: 0.11188207 | AN6: 0 | AO6: 0 | AP6: 0.2317046 | AQ6: 0.16765068 | AR6: 0.081100406 | AS6: 0 | AT6: 0 | AU6: 0.25725776 | AV6: 0 | AW6: 0.1504045 | AX6: 0 | AZ6: =SUM(AJ6:AX6) -> 1 | BB6: {=SQRT(MMULT(MMULT(AJ6:AX6,COV),TRANSPOSE(AJ6:AX6)))} -> 0.019680698 | BC6: {=MMULT($S$3:$AG$3,TRANSPOSE(AJ6:AX6))} -> 0.0085648694 | BD6: Punto portafolio min riesgo | BH6: RIESGO | BI6: 0.011310182 | BL6: =+BL5*500000 -> 2595.4997 | BM6: =+BM5*500000 -> 43626.664 | BN6: =+BN5*500000 -> 0 | BO6: =+BO5*500000 -> 0 | BP6: =+BP5*500000 -> 0 | BQ6: =+BQ5*500000 -> 0 | BR6: =+BR5*500000 -> 0 | BS6: =+BS5*500000 -> 0 | ... BZ6: =+BZ5*500000 -> 0
A7: 41197 | S7: =_xlfn.STDEV.S(INDIRECT(S6)) -> 0.021308393 | T7: =_xlfn.STDEV.S(INDIRECT(T6)) -> 0.030028756 | U7: =_xlfn.STDEV.S(INDIRECT(U6)) -> 0.017232371 | V7: =_xlfn.STDEV.S(INDIRECT(V6)) -> 0.048863256 | W7: =_xlfn.STDEV.S(INDIRECT(W6)) -> 0.01922665 | X7: =_xlfn.STDEV.S(INDIRECT(X6)) -> 0.026446515 | Y7: =_xlfn.STDEV.S(INDIRECT(Y6)) -> 0.026225808 | Z7: =_xlfn.STDEV.S(INDIRECT(Z6)) -> 0.032346317 | ... AG7: =_xlfn.STDEV.S(INDIRECT(AG6)) -> 0.033016847 | AI7: PORT 4 | AJ7: 0.00013575243 | AK7: 0.0025869492 | AL7: 0.002847192 | AM7: 0.0041861477 | AN7: 0.0054938203 | AO7: 0.0018722959 | AP7: 0.0037777932 | AQ7: 0.0047434783 | AR7: 0.0072186994 | AS7: 0.94995826 | AT7: 0.0050301789 | AU7: 0.0013066283 | AV7: 0.0053167364 | AW7: 0.0030846286 | AX7: 0.0024414431 | AZ7: =SUM(AJ7:AX7) -> 1 | BH7: PORTAFOLIO MÁXIMA RENTABILIDAD
A8: 41198 | AI8: PORT 5 | AJ8: 0.00018117258 | AK8: 0.0031944593 | AL8: 0.0007193233 | AM8: 0.0034375172 | AN8: 0.00026458117 | AO8: 0.0020917939 | AP8: 0.0046497363 | AQ8: 0.0050006963 | AR8: 0.031852768 | AS8: 0.93298402 | AT8: 0.0034471991 | AU8: 0.0024615883 | AV8: 0.0040363063 | AW8: 0.005014903 | AX8: 0.00066393012 | AZ8: =SUM(AJ8:AX8) -> 1 | BB8: RATIO DE SHARPE | BC8: =+(BC6-BD12)/BB6 -> 0.40470463 | BH8: RETORNO | BI8: 0.00082066658 | BL8: 4.5801405e-05 | BM8: 0 | BN8: 0 | BO8: 0 | BP8: 0 | BQ8: 0 | BR8: 0 | BS8: 0 | BT8: 0.00063308414 | BU8: 0.99868803 | BV8: 0 | BW8: 0 | BX8: 0 | BY8: 0.00063308414 | BZ8: 0
A9: 41199 | AI9: PORT 6 | AJ9: 0.00023049328 | AK9: 4.7383724e-05 | AL9: 0.003476909 | AM9: 0.0056081958 | AN9: 0.00034521226 | AO9: 0.0059058921 | AP9: 0.0016351774 | AQ9: 0.0026154149 | AR9: 0.032777671 | AS9: 0.93173744 | AT9: 0.0047118272 | AU9: 0.0035339574 | AV9: 0.0026102804 | AW9: 0.0042839601 | AX9: 0.00048018719 | AZ9: =SUM(AJ9:AX9) -> 1 | BH9: RIESGO | BI9: 0.017226873
A10: 41200 | S10: MATRIZ DE VARIANZAS & COVARIANZAS | AI10: PORT 7 | AJ10: 0.00028317024 | AK10: 0.0040110061 | AL10: 0.0063296626 | AM10: 0.0041392926 | AN10: 0.0036687482 | AO10: 0.0024279121 | AP10: 0.00087740326 | AQ10: 0.0027654546 | AR10: 0.023875578 | AS10: 0.93597707 | AT10: 0.0025208046 | AU10: 0.003704076 | AV10: 0.0022182782 | AW10: 0.0049599514 | AX10: 0.002241597 | AZ10: =SUM(AJ10:AX10) -> 1 | BH10: PORTAFOLIO MÍNIMO RIESGO
A11: 41201 | S11: ALICORPC1 | T11: BAP | U11: BBVAC1 | V11: BVN | W11: CPACASC1 | X11: FERREYC1 | Y11: GRAMONC1 | Z11: IFS | AA11: INRETC1 | AB11: LUSURC1 | AC11: MINSURI1 | AD11: NEXAPEC1 | AE11: RELAPAC1 | AF11: UNACEMC1 | AG11: VOLCABC1 | BB11: Rentabilidad diaria | BH11: RETORNO | BI11: 0.00026233375 | BL11: 0.17755376 | BM11: 0.066259661 | BN11: 0.040893252 | BO11: 0.020414541 | BP11: 0.12381282 | BQ11: 0.061423209 | BR11: 0 | BS11: 0.044010075 | BT11: 0.27663136 | BU11: 0.13618045 | BV11: 0 | BW11: 0.0072305833 | BX11: 0 | BY11: 0.045590294 | BZ11: 0
A12: 41204 | R12: ALICORPC1 | S12: =_xlfn.COVARIANCE.S(INDIRECT($R12),INDIRECT(S$11)) -> 0.00045404759 | T12: =_xlfn.COVARIANCE.S(INDIRECT($R12),INDIRECT(T$11)) -> 0.00032041581 | U12: =_xlfn.COVARIANCE.S(INDIRECT($R12),INDIRECT(U$11)) -> 7.9692692e-05 | V12: =_xlfn.COVARIANCE.S(INDIRECT($R12),INDIRECT(V$11)) -> 0.00015164953 | W12: =_xlfn.COVARIANCE.S(INDIRECT($R12),INDIRECT(W$11)) -> 0.00018680715 | X12: =_xlfn.COVARIANCE.S(INDIRECT($R12),INDIRECT(X$11)) -> 0.00039273504 | Y12: =_xlfn.COVARIANCE.S(INDIRECT($R12),INDIRECT(Y$11)) -> 0.00013847582 | Z12: =_xlfn.COVARIANCE.S(INDIRECT($R12),INDIRECT(Z$11)) -> 0.00012091238 | ... AG12: =_xlfn.COVARIANCE.S(INDIRECT($R12),INDIRECT(AG$11)) -> 0.00035017443 | BB12: Activo libre de riesgo | BD12: 0.0006 | BH12: RIESGO | BI12: 0.0084762786
A13: 41205 | R13: BAP | S13: =_xlfn.COVARIANCE.S(INDIRECT($R13),INDIRECT(S$11)) -> 0.00032041581 | T13: =_xlfn.COVARIANCE.S(INDIRECT($R13),INDIRECT(T$11)) -> 0.00090172622 | U13: =_xlfn.COVARIANCE.S(INDIRECT($R13),INDIRECT(U$11)) -> 0.00011990473 | V13: =_xlfn.COVARIANCE.S(INDIRECT($R13),INDIRECT(V$11)) -> 0.0006000621 | W13: =_xlfn.COVARIANCE.S(INDIRECT($R13),INDIRECT(W$11)) -> 0.00018019737 | X13: =_xlfn.COVARIANCE.S(INDIRECT($R13),INDIRECT(X$11)) -> 0.00039272753 | Y13: =_xlfn.COVARIANCE.S(INDIRECT($R13),INDIRECT(Y$11)) -> 0.00012155284 | Z13: =_xlfn.COVARIANCE.S(INDIRECT($R13),INDIRECT(Z$11)) -> 0.00059610381 | ... AG13: =_xlfn.COVARIANCE.S(INDIRECT($R13),INDIRECT(AG$11)) -> 0.00031624337
A14: 41206 | R14: BBVAC1 | S14: =_xlfn.COVARIANCE.S(INDIRECT($R14),INDIRECT(S$11)) -> 7.9692692e-05 | T14: =_xlfn.COVARIANCE.S(INDIRECT($R14),INDIRECT(T$11)) -> 0.00011990473 | U14: =_xlfn.COVARIANCE.S(INDIRECT($R14),INDIRECT(U$11)) -> 0.00029695462 | V14: =_xlfn.COVARIANCE.S(INDIRECT($R14),INDIRECT(V$11)) -> 0.00039931985 | W14: =_xlfn.COVARIANCE.S(INDIRECT($R14),INDIRECT(W$11)) -> 0.00016377772 | X14: =_xlfn.COVARIANCE.S(INDIRECT($R14),INDIRECT(X$11)) -> 0.00017609732 | Y14: =_xlfn.COVARIANCE.S(INDIRECT($R14),INDIRECT(Y$11)) -> -1.9613248e-05 | Z14: =_xlfn.COVARIANCE.S(INDIRECT($R14),INDIRECT(Z$11)) -> 0.00013331141 | ... AG14: =_xlfn.COVARIANCE.S(INDIRECT($R14),INDIRECT(AG$11)) -> 0.0003086485 | AJ14: =+AJ6*600000 -> 0 | AK14: =+AK6*600000 -> 0 | AL14: =+AL6*600000 -> 0 | AM14: =+AM6*600000 -> 67129.24 | AN14: =+AN6*600000 -> 0 | AO14: =+AO6*600000 -> 0 | AP14: =+AP6*600000 -> 139022.76 | AQ14: =+AQ6*600000 -> 100590.41 | ... AX14: =+AX6*600000 -> 0 | BH14: FECHAS 12 MARZO - 11 JUNIO
A15: 41207 | R15: BVN | S15: =_xlfn.COVARIANCE.S(INDIRECT($R15),INDIRECT(S$11)) -> 0.00015164953 | T15: =_xlfn.COVARIANCE.S(INDIRECT($R15),INDIRECT(T$11)) -> 0.0006000621 | U15: =_xlfn.COVARIANCE.S(INDIRECT($R15),INDIRECT(U$11)) -> 0.00039931985 | V15: =_xlfn.COVARIANCE.S(INDIRECT($R15),INDIRECT(V$11)) -> 0.0023876178 | W15: =_xlfn.COVARIANCE.S(INDIRECT($R15),INDIRECT(W$11)) -> 0.00026118596 | X15: =_xlfn.COVARIANCE.S(INDIRECT($R15),INDIRECT(X$11)) -> 0.0002920773 | Y15: =_xlfn.COVARIANCE.S(INDIRECT($R15),INDIRECT(Y$11)) -> 0.00041387703 | Z15: =_xlfn.COVARIANCE.S(INDIRECT($R15),INDIRECT(Z$11)) -> 0.0006389666 | ... AG15: =_xlfn.COVARIANCE.S(INDIRECT($R15),INDIRECT(AG$11)) -> 0.00058439899 | BB15: Monto | BC15: Porcentaje | BH15: PORTAFOLIO ÓPTIMO <-> RATIO SHARP | BL15: PESOS
A16: 41208 | R16: CPACASC1 | S16: =_xlfn.COVARIANCE.S(INDIRECT($R16),INDIRECT(S$11)) -> 0.00018680715 | T16: =_xlfn.COVARIANCE.S(INDIRECT($R16),INDIRECT(T$11)) -> 0.00018019737 | U16: =_xlfn.COVARIANCE.S(INDIRECT($R16),INDIRECT(U$11)) -> 0.00016377772 | V16: =_xlfn.COVARIANCE.S(INDIRECT($R16),INDIRECT(V$11)) -> 0.00026118596 | W16: =_xlfn.COVARIANCE.S(INDIRECT($R16),INDIRECT(W$11)) -> 0.00036966408 | X16: =_xlfn.COVARIANCE.S(INDIRECT($R16),INDIRECT(X$11)) -> 0.00036904704 | Y16: =_xlfn.COVARIANCE.S(INDIRECT($R16),INDIRECT(Y$11)) -> 0.00024528054 | Z16: =_xlfn.COVARIANCE.S(INDIRECT($R16),INDIRECT(Z$11)) -> 0.0002084643 | ... AG16: =_xlfn.COVARIANCE.S(INDIRECT($R16),INDIRECT(AG$11)) -> 0.00046032337 | BA16: BVN | BB16: 67129.24 | BC16: =BB16/$BC$52 -> 0.11188207 | BH16: Retorno/riesgos | BI16: =+BI17/BI18 -> 0.15883711 | BL16: ALICORPC1 | BM16: BAP | BN16: BBVAC1 | BO16: BVN | BP16: CPACASC1 | BQ16: FERREYC1 | BR16: GRAMONC1 | BS16: IFS | BT16: INRETC1 | BU16: LUSURC1 | BV16: MINSURI1 | BW16: NEXAPEC1 | BX16: RELAPAC1 | BY16: UNACEMC1 | BZ16: VOLCABC1
A17: 41211 | R17: FERREYC1 | S17: =_xlfn.COVARIANCE.S(INDIRECT($R17),INDIRECT(S$11)) -> 0.00039273504 | T17: =_xlfn.COVARIANCE.S(INDIRECT($R17),INDIRECT(T$11)) -> 0.00039272753 | U17: =_xlfn.COVARIANCE.S(INDIRECT($R17),INDIRECT(U$11)) -> 0.00017609732 | V17: =_xlfn.COVARIANCE.S(INDIRECT($R17),INDIRECT(V$11)) -> 0.0002920773 | W17: =_xlfn.COVARIANCE.S(INDIRECT($R17),INDIRECT(W$11)) -> 0.00036904704 | X17: =_xlfn.COVARIANCE.S(INDIRECT($R17),INDIRECT(X$11)) -> 0.00069941815 | Y17: =_xlfn.COVARIANCE.S(INDIRECT($R17),INDIRECT(Y$11)) -> 0.00029468429 | Z17: =_xlfn.COVARIANCE.S(INDIRECT($R17),INDIRECT(Z$11)) -> 0.00037457018 | ... AG17: =_xlfn.COVARIANCE.S(INDIRECT($R17),INDIRECT(AG$11)) -> 0.00058139281 | BA17: INRETC | BB17: 235512.18 | BC17: =BB17/$BC$52 -> 0.3925203 | BH17: RETORNO | BI17: 0.0026660945 | BL17: 0 | BM17: 0.069722297 | BN17: 0 | BO17: 0 | BP17: 0 | BQ17: 0 | BR17: 0.18233581 | BS17: 0.018087341 | BT17: 0 | BU17: 0 | BV17: 0.72436604 | BW17: 0 | BX17: 0 | BY17: 0 | BZ17: 0.0054884848
A18: 41212 | R18: GRAMONC1 | S18: =_xlfn.COVARIANCE.S(INDIRECT($R18),INDIRECT(S$11)) -> 0.00013847582 | T18: =_xlfn.COVARIANCE.S(INDIRECT($R18),INDIRECT(T$11)) -> 0.00012155284 | U18: =_xlfn.COVARIANCE.S(INDIRECT($R18),INDIRECT(U$11)) -> -1.9613248e-05 | V18: =_xlfn.COVARIANCE.S(INDIRECT($R18),INDIRECT(V$11)) -> 0.00041387703 | W18: =_xlfn.COVARIANCE.S(INDIRECT($R18),INDIRECT(W$11)) -> 0.00024528054 | X18: =_xlfn.COVARIANCE.S(INDIRECT($R18),INDIRECT(X$11)) -> 0.00029468429 | Y18: =_xlfn.COVARIANCE.S(INDIRECT($R18),INDIRECT(Y$11)) -> 0.00068779303 | Z18: =_xlfn.COVARIANCE.S(INDIRECT($R18),INDIRECT(Z$11)) -> 5.4275263e-05 | ... AG18: =_xlfn.COVARIANCE.S(INDIRECT($R18),INDIRECT(AG$11)) -> 0.00033777983 | BB18: 192494.51 | BC18: =BB18/$BC$52 -> 0.32082418 | BH18: RIESGO | BI18: 0.016785086 | BL18: =+BL17*500000 -> 0 | BM18: =+BM17*500000 -> 34861.148 | BN18: =+BN17*500000 -> 0 | BO18: =+BO17*500000 -> 0 | BP18: =+BP17*500000 -> 0 | BQ18: =+BQ17*500000 -> 0 | BR18: =+BR17*500000 -> 91167.907 | BS18: =+BS17*500000 -> 9043.6704 | ... BZ18: =+BZ17*500000 -> 2744.2424
A19: 41213 | R19: IFS | S19: =_xlfn.COVARIANCE.S(INDIRECT($R19),INDIRECT(S$11)) -> 0.00012091238 | T19: =_xlfn.COVARIANCE.S(INDIRECT($R19),INDIRECT(T$11)) -> 0.00059610381 | U19: =_xlfn.COVARIANCE.S(INDIRECT($R19),INDIRECT(U$11)) -> 0.00013331141 | V19: =_xlfn.COVARIANCE.S(INDIRECT($R19),INDIRECT(V$11)) -> 0.0006389666 | W19: =_xlfn.COVARIANCE.S(INDIRECT($R19),INDIRECT(W$11)) -> 0.0002084643 | X19: =_xlfn.COVARIANCE.S(INDIRECT($R19),INDIRECT(X$11)) -> 0.00037457018 | Y19: =_xlfn.COVARIANCE.S(INDIRECT($R19),INDIRECT(Y$11)) -> 5.4275263e-05 | Z19: =_xlfn.COVARIANCE.S(INDIRECT($R19),INDIRECT(Z$11)) -> 0.0010462842 | ... AG19: =_xlfn.COVARIANCE.S(INDIRECT($R19),INDIRECT(AG$11)) -> 0.00024559065 | BB19: =SUM(BB16:BB18) -> 495135.93 | BH19: PORTAFOLIO MÁXIMA RENTABILIDAD
A20: 41215 | R20: INRETC1 | S20: =_xlfn.COVARIANCE.S(INDIRECT($R20),INDIRECT(S$11)) -> 0.00025804773 | T20: =_xlfn.COVARIANCE.S(INDIRECT($R20),INDIRECT(T$11)) -> 0.00029579551 | U20: =_xlfn.COVARIANCE.S(INDIRECT($R20),INDIRECT(U$11)) -> -2.5539059e-06 | V20: =_xlfn.COVARIANCE.S(INDIRECT($R20),INDIRECT(V$11)) -> 0.00014052811 | W20: =_xlfn.COVARIANCE.S(INDIRECT($R20),INDIRECT(W$11)) -> 0.00010569489 | X20: =_xlfn.COVARIANCE.S(INDIRECT($R20),INDIRECT(X$11)) -> 0.00022367954 | Y20: =_xlfn.COVARIANCE.S(INDIRECT($R20),INDIRECT(Y$11)) -> 0.0001066009 | Z20: =_xlfn.COVARIANCE.S(INDIRECT($R20),INDIRECT(Z$11)) -> 7.4053702e-05 | ... AG20: =_xlfn.COVARIANCE.S(INDIRECT($R20),INDIRECT(AG$11)) -> 0.00028332985 | BH20: RETORNO | BI20: 0.0053153166 | BL20: 0 | BM20: 0 | BN20: 0 | BO20: 1 | BP20: 0 | BQ20: 0 | BR20: 0 | BS20: 0 | BT20: 0 | BU20: 0 | BV20: 0 | BW20: 0 | BX20: 0 | BY20: 0 | BZ20: 0
A21: 41218 | R21: LUSURC1 | S21: =_xlfn.COVARIANCE.S(INDIRECT($R21),INDIRECT(S$11)) -> 5.8575394e-05 | T21: =_xlfn.COVARIANCE.S(INDIRECT($R21),INDIRECT(T$11)) -> 0.00026228811 | U21: =_xlfn.COVARIANCE.S(INDIRECT($R21),INDIRECT(U$11)) -> -6.2920516e-05 | V21: =_xlfn.COVARIANCE.S(INDIRECT($R21),INDIRECT(V$11)) -> 0.00013068474 | W21: =_xlfn.COVARIANCE.S(INDIRECT($R21),INDIRECT(W$11)) -> -8.423267e-05 | X21: =_xlfn.COVARIANCE.S(INDIRECT($R21),INDIRECT(X$11)) -> 7.0282764e-06 | Y21: =_xlfn.COVARIANCE.S(INDIRECT($R21),INDIRECT(Y$11)) -> -6.3285864e-05 | Z21: =_xlfn.COVARIANCE.S(INDIRECT($R21),INDIRECT(Z$11)) -> 0.00017571143 | ... AG21: =_xlfn.COVARIANCE.S(INDIRECT($R21),INDIRECT(AG$11)) -> -0.00018072588 | BH21: RIESGO | BI21: 0.063583709
A22: 41219 | R22: MINSURI1 | S22: =_xlfn.COVARIANCE.S(INDIRECT($R22),INDIRECT(S$11)) -> 0.00015416335 | T22: =_xlfn.COVARIANCE.S(INDIRECT($R22),INDIRECT(T$11)) -> 0.00023793228 | U22: =_xlfn.COVARIANCE.S(INDIRECT($R22),INDIRECT(U$11)) -> 0.00012988685 | V22: =_xlfn.COVARIANCE.S(INDIRECT($R22),INDIRECT(V$11)) -> 0.0002404516 | W22: =_xlfn.COVARIANCE.S(INDIRECT($R22),INDIRECT(W$11)) -> 7.6074978e-05 | X22: =_xlfn.COVARIANCE.S(INDIRECT($R22),INDIRECT(X$11)) -> 0.00019428803 | Y22: =_xlfn.COVARIANCE.S(INDIRECT($R22),INDIRECT(Y$11)) -> 4.1849134e-05 | Z22: =_xlfn.COVARIANCE.S(INDIRECT($R22),INDIRECT(Z$11)) -> 0.00018675263 | ... AG22: =_xlfn.COVARIANCE.S(INDIRECT($R22),INDIRECT(AG$11)) -> 0.00014719532 | BH22: PORTAFOLIO MÍNIMO RIESGO
A23: 41220 | R23: NEXAPEC1 | S23: =_xlfn.COVARIANCE.S(INDIRECT($R23),INDIRECT(S$11)) -> 0.00031200472 | T23: =_xlfn.COVARIANCE.S(INDIRECT($R23),INDIRECT(T$11)) -> 0.00040491811 | U23: =_xlfn.COVARIANCE.S(INDIRECT($R23),INDIRECT(U$11)) -> 7.4682927e-05 | V23: =_xlfn.COVARIANCE.S(INDIRECT($R23),INDIRECT(V$11)) -> 8.7692543e-05 | W23: =_xlfn.COVARIANCE.S(INDIRECT($R23),INDIRECT(W$11)) -> 0.00018541773 | X23: =_xlfn.COVARIANCE.S(INDIRECT($R23),INDIRECT(X$11)) -> 0.00038682167 | Y23: =_xlfn.COVARIANCE.S(INDIRECT($R23),INDIRECT(Y$11)) -> -0.00027357688 | Z23: =_xlfn.COVARIANCE.S(INDIRECT($R23),INDIRECT(Z$11)) -> 0.0006241185 | ... AG23: =_xlfn.COVARIANCE.S(INDIRECT($R23),INDIRECT(AG$11)) -> 0.00045451998 | BH23: RETORNO | BI23: 0.00068341615 | BL23: 0.13545796 | BM23: 0 | BN23: 0.0096668751 | BO23: 0.027922325 | BP23: 0.20915232 | BQ23: 0.0084421662 | BR23: 0.015534076 | BS23: 0 | BT23: 0.11433641 | BU23: 0.093288164 | BV23: 0.28481593 | BW23: 0.10138378 | BX23: 0 | BY23: 0 | BZ23: 0
A24: 41221 | R24: RELAPAC1 | S24: =_xlfn.COVARIANCE.S(INDIRECT($R24),INDIRECT(S$11)) -> 0.00046303774 | T24: =_xlfn.COVARIANCE.S(INDIRECT($R24),INDIRECT(T$11)) -> 0.00059828056 | U24: =_xlfn.COVARIANCE.S(INDIRECT($R24),INDIRECT(U$11)) -> 0.00032702598 | V24: =_xlfn.COVARIANCE.S(INDIRECT($R24),INDIRECT(V$11)) -> 0.00070112568 | W24: =_xlfn.COVARIANCE.S(INDIRECT($R24),INDIRECT(W$11)) -> 0.00050822298 | X24: =_xlfn.COVARIANCE.S(INDIRECT($R24),INDIRECT(X$11)) -> 0.00054526407 | Y24: =_xlfn.COVARIANCE.S(INDIRECT($R24),INDIRECT(Y$11)) -> 0.00024133648 | Z24: =_xlfn.COVARIANCE.S(INDIRECT($R24),INDIRECT(Z$11)) -> 0.00043496407 | ... AG24: =_xlfn.COVARIANCE.S(INDIRECT($R24),INDIRECT(AG$11)) -> 0.00091445896 | BH24: RIESGO | BI24: 0.014614758
A25: 41222 | R25: UNACEMC1 | S25: =_xlfn.COVARIANCE.S(INDIRECT($R25),INDIRECT(S$11)) -> 0.00039492419 | T25: =_xlfn.COVARIANCE.S(INDIRECT($R25),INDIRECT(T$11)) -> 0.00036536925 | U25: =_xlfn.COVARIANCE.S(INDIRECT($R25),INDIRECT(U$11)) -> 0.00029673658 | V25: =_xlfn.COVARIANCE.S(INDIRECT($R25),INDIRECT(V$11)) -> 0.00060974146 | W25: =_xlfn.COVARIANCE.S(INDIRECT($R25),INDIRECT(W$11)) -> 0.00043536168 | X25: =_xlfn.COVARIANCE.S(INDIRECT($R25),INDIRECT(X$11)) -> 0.00060293724 | Y25: =_xlfn.COVARIANCE.S(INDIRECT($R25),INDIRECT(Y$11)) -> 0.00041087539 | Z25: =_xlfn.COVARIANCE.S(INDIRECT($R25),INDIRECT(Z$11)) -> 0.00029115744 | ... AG25: =_xlfn.COVARIANCE.S(INDIRECT($R25),INDIRECT(AG$11)) -> 0.0007665832
A26: 41225 | R26: VOLCABC1 | S26: =_xlfn.COVARIANCE.S(INDIRECT($R26),INDIRECT(S$11)) -> 0.00035017443 | T26: =_xlfn.COVARIANCE.S(INDIRECT($R26),INDIRECT(T$11)) -> 0.00031624337 | U26: =_xlfn.COVARIANCE.S(INDIRECT($R26),INDIRECT(U$11)) -> 0.0003086485 | V26: =_xlfn.COVARIANCE.S(INDIRECT($R26),INDIRECT(V$11)) -> 0.00058439899 | W26: =_xlfn.COVARIANCE.S(INDIRECT($R26),INDIRECT(W$11)) -> 0.00046032337 | X26: =_xlfn.COVARIANCE.S(INDIRECT($R26),INDIRECT(X$11)) -> 0.00058139281 | Y26: =_xlfn.COVARIANCE.S(INDIRECT($R26),INDIRECT(Y$11)) -> 0.00033777983 | Z26: =_xlfn.COVARIANCE.S(INDIRECT($R26),INDIRECT(Z$11)) -> 0.00024559065 | ... AG26: =_xlfn.COVARIANCE.S(INDIRECT($R26),INDIRECT(AG$11)) -> 0.0010901122
A27: 41226
A28: 41227
A29: 41228 | BF29: CARTERA INICIAL ESCOGIDA | BG29: INFORMACIÓN
A30: 41229 | BG30: FECHAS 27 MARZO - 11 JUNIO | BH30: PORTAFOLIO ÓPTIMO <-> RATIO SHARP | BL30: PESOS
A31: 41232 | BH31: Retorno/riesgos | BI31: =+BI32/BI33 -> 0.2274658 | BL31: ALICORPC1 | BM31: BAP | BN31: BBVAC1 | BO31: BVN | BP31: CPACASC1 | BQ31: FERREYC1 | BR31: GRAMONC1 | BS31: IFS | BT31: INRETC1 | BU31: LUSURC1 | BV31: MINSURI1 | BW31: NEXAPEC1 | BX31: RELAPAC1 | BY31: UNACEMC1 | BZ31: VOLCABC1
A32: 41233 | BH32: RETORNO | BI32: 0.0041284369 | BL32: 0.12962015 | BM32: 0 | BN32: 0 | BO32: 0.10892295 | BP32: 0 | BQ32: 0 | BR32: 0 | BS32: 0 | BT32: 0.40032951 | BU32: 0.054822302 | BV32: 0.3063051 | BW32: 0 | BX32: 0 | BY32: 0 | BZ32: 0
A33: 41234 | BH33: RIESGO | BI33: 0.018149704 | BL33: =+BL32*500000 -> 64810.074 | BM33: =+BM32*600000 -> 0 | BN33: =+BN32*600000 -> 0 | BO33: =+BO32*600000 -> 65353.769 | BP33: =+BP32*600000 -> 0 | BQ33: =+BQ32*600000 -> 0 | BR33: =+BR32*600000 -> 0 | BS33: =+BS32*600000 -> 0 | BT33: =+BT32*600000 -> 240197.7 | ... BZ33: =+BZ32*600000 -> 0
A34: 41235 | BH34: PORTAFOLIO MÁXIMA RENTABILIDAD
A35: 41236 | BH35: RETORNO | BI35: 0.0063278305 | BL35: 0 | BM35: 0 | BN35: 0 | BO35: 0 | BP35: 0 | BQ35: 0 | BR35: 1 | BS35: 0 | BT35: 0 | BU35: 0 | BV35: 0 | BW35: 0 | BX35: 0 | BY35: 0 | BZ35: 0
A36: 41239 | BH36: RIESGO | BI36: 0.049648963
A37: 41240 | BH37: PORTAFOLIO MÍNIMO RIESGO
A38: 41241 | BH38: RETORNO | BI38: 0.0014685353 | BL38: 0.13545796 | BM38: 0 | BN38: 0.0096668751 | BO38: 0.027922325 | BP38: 0.20915232 | BQ38: 0.0084421662 | BR38: 0.015534076 | BS38: 0 | BT38: 0.11433641 | BU38: 0.093288164 | BV38: 0.28481593 | BW38: 0.10138378 | BX38: 0 | BY38: 0 | BZ38: 0
A39: 41242 | BH39: RIESGO | BI39: 0.013761765
A40: 41243
...

Sheet rprecios
A1: FECHA | B1: ALICORPC1 | C1: BAP | D1: BBVAC1 | E1: BVN | F1: CPACASC1 | G1: FERREYC1 | H1: GRAMONC1 | I1: IFS | J1: INRETC1 | K1: LUSURC1 | L1: MINSURI1 | M1: NEXAPEC1 | N1: RELAPAC1 | O1: UNACEMC1 | P1: VOLCABC1
A2: 41191 | B2: 6.82 | C2: 119.02 | D2: 4.58 | E2: 37.25 | F2: 5.68 | G2: 1.8 | H2: 8.38 | I2: 30.32 | J2: 20.1 | K2: 7.35 | L2: 2.31 | M2: 3.52 | N2: 0.47 | O2: 2.96 | P2: 2.3
A3: 41192 | B3: 6.86 | C3: 119.76 | D3: 4.6 | E3: 37.05 | F3: 5.68 | G3: 1.79 | H3: 8.43 | I3: 30.51 | J3: 20.3 | K3: 7.46 | L3: 2.29 | M3: 3.51 | N3: 0.47 | O3: 2.97 | P3: 2.26
A4: 41193 | B4: 6.9 | C4: 119.03 | D4: 4.59 | E4: 37.3 | F4: 5.77 | G4: 1.74 | H4: 8.43 | I4: 30.51 | J4: 20.09 | K4: 7.46 | L4: 2.31 | M4: 3.51 | N4: 0.47 | O4: 3.04 | P4: 2.28
A5: 41194 | B5: 6.91 | C5: 117.78 | D5: 4.56 | E5: 37.1 | F5: 5.77 | G5: 1.74 | H5: 8.57 | I5: 30.51 | J5: 20.2 | K5: 7.46 | L5: 2.29 | M5: 3.51 | N5: 0.48 | O5: 3.06 | P5: 2.21
A6: 41197 | B6: 6.91 | C6: 117.79 | D6: 4.56 | E6: 36.6 | F6: 5.73 | G6: 1.76 | H6: 8.57 | I6: 30.64 | J6: 20.4 | K6: 7.51 | L6: 2.29 | M6: 3.51 | N6: 0.48 | O6: 3.08 | P6: 2.25
A7: 41198 | B7: 6.99 | C7: 118.39 | D7: 4.56 | E7: 36.3 | F7: 5.77 | G7: 1.76 | H7: 8.66 | I7: 30.64 | J7: 20.4 | K7: 7.59 | L7: 2.32 | M7: 3.51 | N7: 0.48 | O7: 3.11 | P7: 2.26
A8: 41199 | B8: 7.06 | C8: 118.53 | D8: 4.56 | E8: 36.7 | F8: 5.82 | G8: 1.75 | H8: 8.67 | I8: 30.42 | J8: 20.4 | K8: 7.59 | L8: 2.33 | M8: 3.49 | N8: 0.48 | O8: 3.11 | P8: 2.29
A9: 41200 | B9: 7.26 | C9: 117.82 | D9: 4.53 | E9: 36.15 | F9: 5.82 | G9: 1.75 | H9: 8.74 | I9: 30.42 | J9: 20.2 | K9: 7.64 | L9: 2.33 | M9: 3.47 | N9: 0.48 | O9: 3.11 | P9: 2.27
A10: 41201 | B10: 7.4 | C10: 118.44 | D10: 4.53 | E10: 36 | F10: 5.82 | G10: 1.75 | H10: 8.74 | I10: 30.42 | J10: 20 | K10: 7.69 | L10: 2.32 | M10: 3.43 | N10: 0.47 | O10: 3.1 | P10: 2.27
A11: 41204 | B11: 7.51 | C11: 118.63 | D11: 4.53 | E11: 36.4 | F11: 5.82 | G11: 1.74 | H11: 8.67 | I11: 30.14 | J11: 19.8 | K11: 7.65 | L11: 2.29 | M11: 3.41 | N11: 0.47 | O11: 3.11 | P11: 2.27
A12: 41205 | B12: 7.39 | C12: 118.16 | D12: 4.46 | E12: 35.5 | F12: 5.73 | G12: 1.74 | H12: 8.67 | I12: 29.6 | J12: 19.4 | K12: 7.65 | L12: 2.26 | M12: 3.31 | N12: 0.46 | O12: 3.08 | P12: 2.18
A13: 41206 | B13: 7.28 | C13: 118.72 | D13: 4.46 | E13: 35 | F13: 5.7 | G13: 1.74 | H13: 8.62 | I13: 29.6 | J13: 19.25 | K13: 7.64 | L13: 2.25 | M13: 3.31 | N13: 0.47 | O13: 3.07 | P13: 2.13
... A1854: 43885 | B1854: 9.05 | C1854: 194.11 | D1854: 3.36 | E1854: 12.2 | F1854: 6.1 | G1854: 2.05 | H1854: 1.85 | I1854: 40.88 | J1854: 36.75 | K1854: 25.45 | L1854: 1.61 | M1854: 3.42 | N1854: 0.099 | O1854: 1.96 | P1854: 0.5
A1855: 43886 | B1855: 9 | C1855: 187.85 | D1855: 3.36 | E1855: 11.8 | F1855: 6.05 | G1855: 2.03 | H1855: 1.78 | I1855: 40.6 | J1855: 36.4 | K1855: 25 | L1855: 1.6 | M1855: 3.35 | N1855: 0.097 | O1855: 1.95 | P1855: 0.48 | S1855: =MIN(C1855:C1930) -> 117.94 | T1855: =INDEX(A1855:C1930,MATCH(S1855,C1855:C1930,0),1) -> 43917
A1856: 43887 | B1856: 8.9 | C1856: 189.6 | D1856: 3.37 | E1856: 12.4 | F1856: 6 | G1856: 2 | H1856: 1.78 | I1856: 40 | J1856: 35.95 | K1856: 25 | L1856: 1.58 | M1856: 3.35 | N1856: 0.095 | O1856: 1.94 | P1856: 0.466
A1857: 43888 | B1857: 8.62 | C1857: 183.93 | D1857: 3.35 | E1857: 12.38 | F1857: 5.95 | G1857: 2 | H1857: 1.65 | I1857: 38.45 | J1857: 35.1 | K1857: 24.5 | L1857: 1.52 | M1857: 3.25 | N1857: 0.083 | O1857: 1.91 | P1857: 0.44
A1858: 43889 | B1858: 8.5 | C1858: 181.2 | D1858: 3.3 | E1858: 11.24 | F1858: 5.85 | G1858: 1.99 | H1858: 1.67 | I1858: 37.82 | J1858: 34.3 | K1858: 27 | L1858: 1.48 | M1858: 3.2 | N1858: 0.085 | O1858: 1.97 | P1858: 0.438
A1859: 43892 | B1859: 8.55 | C1859: 190 | D1859: 3.3 | E1859: 10.82 | F1859: 6.15 | G1859: 2 | H1859: 1.72 | I1859: 39.5 | J1859: 34.5 | K1859: 26 | L1859: 1.5 | M1859: 3.2 | N1859: 0.088 | O1859: 1.96 | P1859: 0.465
A1860: 43893 | B1860: 8.7 | C1860: 187.45 | D1860: 3.29 | E1860: 11.17 | F1860: 6.1 | G1860: 2.08 | H1860: 1.75 | I1860: 38.5 | J1860: 34 | K1860: 25.9 | L1860: 1.52 | M1860: 3.2 | N1860: 0.088 | O1860: 1.96 | P1860: 0.5
A1861: 43894 | B1861: 8.75 | C1861: 198.08 | D1861: 3.3 | E1861: 11 | F1861: 6.1 | G1861: 2.1 | H1861: 1.75 | I1861: 39.4 | J1861: 34.2 | K1861: 25.99 | L1861: 1.52 | M1861: 3.2 | N1861: 0.09 | O1861: 1.95 | P1861: 0.475
A1862: 43895 | B1862: 8.79 | C1862: 191.01 | D1862: 3.3 | E1862: 11.11 | F1862: 6.1 | G1862: 2.09 | H1862: 1.73 | I1862: 38.5 | J1862: 34.12 | K1862: 25.9 | L1862: 1.5 | M1862: 3.2 | N1862: 0.088 | O1862: 1.93 | P1862: 0.46
A1863: 43896 | B1863: 8.6 | C1863: 186.7 | D1863: 3.25 | E1863: 10.46 | F1863: 6 | G1863: 2 | H1863: 1.69 | I1863: 36.53 | J1863: 33 | K1863: 25 | L1863: 1.45 | M1863: 3.2 | N1863: 0.08 | O1863: 1.89 | P1863: 0.435
A1864: 43899 | B1864: 8.31 | C1864: 175 | D1864: 3.2 | E1864: 9.5 | F1864: 5.8 | G1864: 1.92 | H1864: 1.59 | I1864: 32.62 | J1864: 31.9 | K1864: 24.48 | L1864: 1.41 | M1864: 3 | N1864: 0.076 | O1864: 1.89 | P1864: 0.406
A1865: 43900 | B1865: 8.4 | C1865: 179.4 | D1865: 3.2 | E1865: 9.45 | F1865: 6 | G1865: 1.93 | H1865: 1.65 | I1865: 36 | J1865: 32 | K1865: 26 | L1865: 1.48 | M1865: 3 | N1865: 0.079 | O1865: 1.8 | P1865: 0.44
A1866: 43901 | B1866: 8.23 | C1866: 171.55 | D1866: 3.15 | E1866: 8.58 | F1866: 5.9 | G1866: 1.89 | H1866: 1.56 | I1866: 35.5 | J1866: 31.5 | K1866: 25.5 | L1866: 1.48 | M1866: 2.88 | N1866: 0.08 | O1866: 1.7 | P1866: 0.41
A1867: 43902 | B1867: 7.4 | C1867: 151 | D1867: 2.9 | E1867: 6.6 | F1867: 5.7 | G1867: 1.78 | H1867: 1.46 | I1867: 30.65 | J1867: 30 | K1867: 24.5 | L1867: 1.43 | M1867: 2.6 | N1867: 0.08 | O1867: 1.65 | P1867: 0.39
... A1934: 44000 | B1934: 8.27 | C1934: 150.25 | D1934: 2.7 | E1934: 8.61 | F1934: 5.1 | G1934: 1.42 | H1934: 1.62 | I1934: 30.45 | J1934: 34.5 | K1934: 26.03 | L1934: 1.54 | M1934: 2.24 | N1934: 0.066 | O1934: 1.6 | P1934: 0.35

Sheet basedatos
A1: FECHA | B1: ALICORPC1 | C1: BAP | D1: BBVAC1 | E1: BVN | F1: CPACASC1 | G1: FERREYC1 | H1: GRAMONC1 | I1: IFS | J1: INRETC1 | K1: LUSURC1 | L1: MINSURI1 | M1: NEXAPEC1 | N1: RELAPAC1 | O1: UNACEMC1 | P1: VOLCABC1 | Q1: Contar
A2: 41191 | B2: 6.82 | C2: 119.02 | D2: 4.58 | E2: 37.25 | F2: 5.68 | G2: 1.8 | H2: 8.38 | I2: 30.32 | J2: 20.1 | K2: 7.35 | L2: 2.31 | M2: 3.52 | N2: 0.47 | O2: 2.96 | P2: 2.3 | Q2: 15
A3: 41192 | B3: 6.86 | C3: 119.76 | D3: 4.6 | E3: 37.05 | F3: 5.68 | G3: 1.79 | H3: 8.43 | I3: 30.51 | J3: 20.3 | K3: 7.46 | L3: 2.29 | M3: 3.51 | N3: 0.47 | O3: 2.97 | P3: 2.26 | Q3: 15
A4: 41193 | B4: 6.9 | C4: 119.03 | D4: 4.59 | E4: 37.3 | F4: 5.77 | G4: 1.74 | H4: 8.43 | I4: 30.51 | J4: 20.09 | K4: 7.46 | L4: 2.31 | M4: 3.51 | N4: 0.47 | O4: 3.04 | P4: 2.28 | Q4: 15
A5: 41194 | B5: 6.91 | C5: 117.78 | D5: 4.56 | E5: 37.1 | F5: 5.77 | G5: 1.74 | H5: 8.57 | I5: 30.51 | J5: 20.2 | K5: 7.46 | L5: 2.29 | M5: 3.51 | N5: 0.48 | O5: 3.06 | P5: 2.21 | Q5: 15
A6: 41197 | B6: 6.91 | C6: 117.79 | D6: 4.56 | E6: 36.6 | F6: 5.73 | G6: 1.76 | H6: 8.57 | I6: 30.64 | J6: 20.4 | K6: 7.51 | L6: 2.29 | M6: 3.51 | N6: 0.48 | O6: 3.08 | P6: 2.25 | Q6: 15
A7: 41198 | B7: 6.99 | C7: 118.39 | D7: 4.56 | E7: 36.3 | F7: 5.77 | G7: 1.76 | H7: 8.66 | I7: 30.64 | J7: 20.4 | K7: 7.59 | L7: 2.32 | M7: 3.51 | N7: 0.48 | O7: 3.11 | P7: 2.26 | Q7: 15
A8: 41199 | B8: 7.06 | C8: 118.53 | D8: 4.56 | E8: 36.7 | F8: 5.82 | G8: 1.75 | H8: 8.67 | I8: 30.42 | J8: 20.4 | K8: 7.59 | L8: 2.33 | M8: 3.49 | N8: 0.48 | O8: 3.11 | P8: 2.29 | Q8: 15
A9: 41200 | B9: 7.26 | C9: 117.82 | D9: 4.53 | E9: 36.15 | F9: 5.82 | G9: 1.75 | H9: 8.74 | I9: 30.42 | J9: 20.2 | K9: 7.64 | L9: 2.33 | M9: 3.47 | N9: 0.48 | O9: 3.11 | P9: 2.27 | Q9: 15
A10: 41201 | B10: 7.4 | C10: 118.44 | D10: 4.53 | E10: 36 | F10: 5.82 | G10: 1.75 | H10: #N/A | I10: #N/A | J10: 20 | K10: 7.69 | L10: 2.32 | M10: 3.43 | N10: 0.47 | O10: 3.1 | P10: 2.27 | Q10: 13
A11: 41204 | B11: 7.51 | C11: 118.63 | D11: 4.53 | E11: 36.4 | F11: 5.82 | G11: 1.74 | H11: 8.67 | I11: 30.14 | J11: 19.8 | K11: 7.65 | L11: 2.29 | M11: 3.41 | N11: 0.47 | O11: 3.11 | P11: 2.27 | Q11: 15
A12: 41205 | B12: 7.39 | C12: 118.16 | D12: 4.46 | E12: 35.5 | F12: 5.73 | G12: 1.74 | H12: #N/A | I12: 29.6 | J12: 19.4 | K12: 7.65 | L12: 2.26 | M12: 3.31 | N12: 0.46 | O12: 3.08 | P12: 2.18 | Q12: 14
A13: 41206 | B13: 7.28 | C13: 118.72 | D13: 4.46 | E13: 35 | F13: 5.7 | G13: 1.74 | H13: 8.62 | I13: #N/A | J13: 19.25 | K13: 7.64 | L13: 2.25 | M13: 3.31 | N13: 0.47 | O13: 3.07 | P13: 2.13 | Q13: 14
A14: 41207 | B14: 7.25 | C14: 120.56 | D14: 4.46 | E14: 35.3 | F14: 5.73 | G14: 1.74 | H14: #N/A | I14: 29.6 | J14: 19.2 | K14: 7.64 | L14: 2.27 | M14: 3.32 | N14: 0.47 | O14: 3.06 | P14: 2.12 | Q14: 14
A15: 41208 | B15: 7.16 | C15: 119.73 | D15: 4.46 | E15: 35.2 | F15: 5.7 | G15: 1.74 | H15: #N/A | I15: 29.41 | J15: 19.25 | K15: 7.62 | L15: 2.25 | M15: 3.26 | N15: 0.46 | O15: 3.05 | P15: 2.13 | Q15: 14
A16: 41211 | B16: 7.16 | C16: 119.67 | D16: #N/A | E16: 35 | F16: 5.68 | G16: 1.74 | H16: 8.57 | I16: 29.6 | J16: #N/A | K16: #N/A | L16: 2.25 | M16: 3.28 | N16: 0.46 | O16: 3.04 | P16: 2.13 | Q16: 12
A17: 41212 | B17: 7.16 | C17: #N/A | D17: #N/A | E17: #N/A | F17: 5.68 | G17: 1.73 | H17: 8.57 | I17: #N/A | J17: 19.3 | K17: #N/A | L17: 2.24 | M17: #N/A | N17: 0.46 | O17: 3.03 | P17: 2.14 | Q17: 9
A18: 41213 | B18: 7.16 | C18: 121.47 | D18: 4.46 | E18: 35.51 | F18: 5.82 | G18: 1.72 | H18: 8.71 | I18: 29.14 | J18: 19.35 | K18: 7.62 | L18: 2.23 | M18: 3.31 | N18: 0.45 | O18: 3.03 | P18: 2.03 | Q18: 15
A19: 41215 | B19: 7.32 | C19: 124.92 | D19: 4.46 | E19: 34.68 | F19: 5.79 | G19: 1.71 | H19: 8.67 | I19: 29.14 | J19: 19.35 | K19: 7.69 | L19: 2.21 | M19: #N/A | N19: 0.45 | O19: 3.03 | P19: 2.12 | Q19: 14
A20: 41218 | B20: 7.39 | C20: 124.38 | D20: 4.49 | E20: 34.1 | F20: 5.87 | G20: 1.72 | H20: 8.71 | I20: 29.32 | J20: 19.5 | K20: 7.69 | L20: 2.23 | M20: 3.31 | N20: 0.46 | O20: 3.03 | P20: 2.13 | Q20: 15
A21: 41219 | B21: 7.48 | C21: 125.82 | D21: 4.55 | E21: 35 | F21: 5.94 | G21: 1.73 | H21: 8.7 | I21: 29.55 | J21: 19.42 | K21: 7.69 | L21: 2.21 | M21: 3.31 | N21: 0.45 | O21: 3.05 | P21: 2.05 | Q21: 15
A22: 41220 | B22: 7.45 | C22: 123.64 | D22: 4.56 | E22: 35.15 | F22: 6.02 | G22: 1.73 | H22: 8.7 | I22: 29.14 | J22: 19.4 | K22: 7.7 | L22: 2.24 | M22: 3.31 | N22: 0.45 | O22: 3.05 | P22: 2.02 | Q22: 15
A23: 41221 | B23: 7.5 | C23: 125.82 | D23: 4.54 | E23: 35.7 | F23: 6.04 | G23: 1.74 | H23: 8.62 | I23: 29.51 | J23: 19.45 | K23: 7.7 | L23: 2.27 | M23: 3.31 | N23: 0.46 | O23: 3.08 | P23: 2.08 | Q23: 15
A24: 41222 | B24: 7.5 | C24: 128.18 | D24: 4.57 | E24: 35.79 | F24: 6.1 | G24: 1.75 | H24: 8.53 | I24: #N/A | J24: 19.4 | K24: 7.7 | L24: 2.25 | M24: #N/A | N24: 0.46 | O24: 3.08 | P24: 2.07 | Q24: 13
A25: 41225 | B25: 7.5 | C25: 129.6 | D25: 4.58 | E25: 35.67 | F25: 6.18 | G25: 1.76 | H25: 8.51 | I25: 29.41 | J25: 19.5 | K25: 7.82 | L25: 2.22 | M25: #N/A | N25: 0.46 | O25: 3.08 | P25: 2.07 | Q25: 14
A26: 41226 | B26: 7.55 | C26: 129.6 | D26: 4.63 | E26: 35.45 | F26: 6.3 | G26: 1.74 | H26: 8.54 | I26: 29.87 | J26: 19.7 | K26: 7.92 | L26: 2.21 | M26: 3.31 | N26: 0.44 | O26: 3.18 | P26: 2.09 | Q26: 15
A27: 41227 | B27: 7.55 | C27: 128.66 | D27: 4.56 | E27: 33.5 | F27: 6.3 | G27: 1.74 | H27: 8.54 | I27: 29.6 | J27: 19.5 | K27: 7.92 | L27: 2.15 | M27: 3.29 | N27: 0.43 | O27: 3.16 | P27: 1.98 | Q27: 15
A28: 41228 | B28: 7.59 | C28: 127.97 | D28: 4.62 | E28: 33.45 | F28: 6.3 | G28: 1.71 | H28: 8.53 | I28: 29.96 | J28: 19.5 | K28: 7.92 | L28: 2.14 | M28: 3.26 | N28: 0.42 | O28: 3.12 | P28: 1.74 | Q28: 15
A29: 41229 | B29: 7.64 | C29: 128.99 | D29: 4.58 | E29: 33.29 | F29: 6.15 | G29: 1.7 | H29: 8.55 | I29: 29.6 | J29: 19.5 | K29: 7.92 | L29: #N/A | M29: 3.22 | N29: 0.43 | O29: 3.14 | P29: 1.75 | Q29: 14
A30: 41232 | B30: 7.79 | C30: 130.93 | D30: 4.67 | E30: 33.8 | F30: 6.35 | G30: 1.7 | H30: 8.64 | I30: 29.78 | J30: 19.5 | K30: 7.96 | L30: 2.13 | M30: 3.22 | N30: 0.43 | O30: 3.22 | P30: 1.77 | Q30: 15
A31: 41233 | B31: 7.79 | C31: 130.93 | D31: 4.69 | E31: 33.3 | F31: 6.41 | G31: 1.7 | H31: 8.82 | I31: 29.78 | J31: 19.5 | K31: 7.96 | L31: 2.13 | M31: 3.23 | N31: 0.43 | O31: 3.2 | P31: 1.75 | Q31: 15
A32: 41234 | B32: 7.84 | C32: 131.85 | D32: 4.73 | E32: 33.8 | F32: 6.4 | G32: 1.7 | H32: 8.88 | I32: 30.05 | J32: 19.5 | K32: 7.95 | L32: 2.1 | M32: 3.18 | N32: 0.42 | O32: 3.2 | P32: 1.77 | Q32: 15
A33: 41235 | B33: 7.86 | C33: 131.97 | D33: 4.73 | E33: #N/A | F33: 6.4 | G33: 1.7 | H33: 8.83 | I33: 29.96 | J33: 19.7 | K33: 7.96 | L33: 2.09 | M33: 3.23 | N33: 0.42 | O33: 3.2 | P33: 1.79 | Q33: 14
A34: 41236 | B34: 7.89 | C34: 130.93 | D34: 4.73 | E34: 34 | F34: 6.35 | G34: 1.7 | H34: 8.83 | I34: 30.05 | J34: 19.6 | K34: 7.92 | L34: 2.08 | M34: 3.18 | N34: 0.43 | O34: 3.2 | P34: 1.88 | Q34: 15
A35: 41239 | B35: 7.98 | C35: 131.64 | D35: 4.77 | E35: 33.92 | F35: 6.39 | G35: 1.7 | H35: 8.96 | I35: 30.53 | J35: 19.7 | K35: 7.96 | L35: 2.07 | M35: 3.16 | N35: 0.43 | O35: 3.19 | P35: 1.9 | Q35: 15
A36: 41240 | B36: 7.89 | C36: 130.55 | D36: #N/A | E36: 33 | F36: 6.4 | G36: 1.69 | H36: 9.16 | I36: 30.51 | J36: 19.85 | K36: 7.92 | L36: 1.99 | M36: 3.18 | N36: 0.43 | O36: 3.17 | P36: 2 | Q36: 14
A37: 41241 | B37: 7.84 | C37: 130.57 | D37: 4.79 | E37: 32.82 | F37: 6.4 | G37: 1.7 | H37: 9.2 | I37: 30.51 | J37: #N/A | K37: 7.92 | L37: 1.99 | M37: 3.14 | N37: 0.43 | O37: 3.13 | P37: 1.95 | Q37: 14
A38: 41242 | B38: 7.94 | C38: 132.82 | D38: 4.79 | E38: 33.18 | F38: 6.35 | G38: 1.7 | H38: 9.2 | I38: 31.05 | J38: 20 | K38: #N/A | L38: 1.99 | M38: 3.14 | N38: 0.43 | O38: 3.13 | P38: 1.98 | Q38: 14
A39: 41243 | B39: 7.81 | C39: 132.44 | D39: 4.79 | E39: 32.25 | F39: 6.35 | G39: 1.7 | H39: 9.16 | I39: 31.51 | J39: 20.4 | K39: 7.91 | L39: 1.93 | M39: 3.13 | N39: 0.42 | O39: 3.11 | P39: 1.98 | Q39: 15
A40: 41246 | B40: 7.9 | C40: 131.02 | D40: 4.89 | E40: 32.4 | F40: 6.55 | G40: 1.71 | H40: 9.16 | I40: 31.87 | J40: 20.5 | K40: 7.92 | L40: 1.99 | M40: 3.16 | N40: 0.43 | O40: 3.11 | P40: 2.06 | Q40: 15
...
